# 异常

## 定义

函数A捕捉函数C发出的异常
1. 谁捕捉异常？A
2. 谁抛出异常？C
3. 捕捉到异常后怎么处理？随A



C++异常操作的语法规则如下：

- `throw`语句：用于抛出异常。可以抛出任何类型的数据，包括自定义类型。
- `try`语句块：用于检测异常。`try`语句块中的代码被称为受保护代码，因为它们受到异常处理机制的保护。
- `catch`语句块：用于捕获异常并处理它。`catch`语句块中的代码被称为异常处理代码，因为它们用于处理异常情况。

当程序运行到`throw`语句时，会抛出一个异常。`try`语句块用于检测异常，`catch`语句块用于捕获异常并处理它。当`try`语句块中的代码发生异常时，程序会跳转到与之对应的`catch`语句块中执行相应的处理代码。

[(1) 【从 C 向 C++ 进阶】- 对 C 的语法拓展 - 异常处理_c 高级语法 异常_☆星轨★的博客-CSDN博客.]( https://blog.csdn.net/qq_35692077/article/details/102761560)

[(2) 【C++】：异常机制语法 - 掘金.]( https://juejin.cn/post/7112938840641241102)

[(3) C++异常处理（try catch throw）完全攻略 - C语言中文网.]( http://c.biancheng.net/view/422.html)

[(4) C++ 异常处理 | 菜鸟教程.](https://www.runoob.com/cplusplus/cpp-exceptions-handling.html)

[(5) try-finally 语句 | Microsoft Learn.]( https://learn.microsoft.com/zh-cn/cpp/cpp/try-finally-statement?view=msvc-170)



## 例程1

- 多层调用，顶层能直接捕获底层函数的异常抛出

```C++

#include <iostream>
#include <string.h>
#include <unistd.h>

using namespace std;

void C()
{
	throw 1;
}

void B()
{
	C();
}

void A()
{
	try {
		B();
	} catch (int i)
	{
		cout<<"catch exception "<<i<<endl;
	}
}


int main(int argc, char **argv)
{
	A();
	return 0;
}

```

执行结果：

 ![image-20230521182642974](https://pic-1304959529.cos.ap-guangzhou.myqcloud.com/DB/image-20230521182642974.png)



## 例程2

- 捕捉异常的类型

```c++

#include <iostream>
#include <string.h>
#include <unistd.h>
#include <stdlib.h>

using namespace std;

void C(int i)
{
	int a = 1;
	double b= 1.2;
	float c = 1.3;

	if (i == 0)
	{
		cout<<"In C, it is OK"<<endl;
	}
	else if (i == 1)
		throw a;
	else if (i == 2)
		throw b;
	else 
		throw c;
}

void B(int i)
{
	cout<<"call C ..."<<endl;
	C(i);
	cout<<"After call C"<<endl;
}

void A(int i)
{
	try {
		B(i);
	} catch (int j)
	{
		cout<<"catch exception "<<j<<endl;
	}
}


int main(int argc, char **argv)
{
	int i;
	if (argc != 2)
	{
		cout<<"Usage: "<<endl;
		cout<<argv[0]<<" <0|1|2|3>"<<endl;
		return -1;
	}

	//将字符串转换成无符号长整型
	i = strtoul(argv[1], NULL, 0);

	A(i);
	
	return 0;
}

```

 ![image-20230521185502869](https://pic-1304959529.cos.ap-guangzhou.myqcloud.com/DB/image-20230521185502869.png)

```C++
catch (int j) //只捕捉了int数据，如果抛回来的异常时double类型，就会导致程序崩溃
```



## 例程3

- 增加其他异常的捕捉

```c++

#include <iostream>
#include <string.h>
#include <unistd.h>
#include <stdlib.h>

using namespace std;

void C(int i)
{
	int a = 1;
	double b= 1.2;
	float c = 1.3;

	if (i == 0)
	{
		cout<<"In C, it is OK"<<endl;
	}
	else if (i == 1)
		throw a;
	else if (i == 2)
		throw b;
	else 
		throw c;
}

void B(int i)
{
	cout<<"call C ..."<<endl;
	C(i);
	cout<<"After call C"<<endl;
}

void A(int i)
{
	try {
		B(i);
	} catch (int j)
	{
		cout<<"catch int exception "<<j<<endl;
	} catch (double d)
	{
		cout<<"catch double exception "<<d<<endl;
	} catch (...){
		cout<<"catch other exception "<<endl;
	}
}


int main(int argc, char **argv)
{
	int i;
	if (argc != 2)
	{
		cout<<"Usage: "<<endl;
		cout<<argv[0]<<" <0|1|2|3>"<<endl;
		return -1;
	}

	i = strtoul(argv[1], NULL, 0);

	A(i);
	
	return 0;
}
```

 ![image-20230521185818453](https://pic-1304959529.cos.ap-guangzhou.myqcloud.com/DB/image-20230521185818453.png)



## 例程4

- 如果异常抛出来的是某个实例化对象如何处理

```c++

#include <iostream>
#include <string.h>
#include <unistd.h>
#include <stdlib.h>

using namespace std;

class MyException
{
public:
	void what(void)
	{
		cout << "This is MyException" << endl;
	}
};

void C(int i)
{
	int a = 1;
	double b = 1.2;
	float c = 1.3;

	if (i == 0)
	{
		cout << "In C, it is OK" << endl;
	}
	else if (i == 1)
		throw a;
	else if (i == 2)
		throw b;
	else if (i == 3)
		throw c;
	else if (i == 4)
		throw MyException();
}

void B(int i)
{
	cout << "call C ..." << endl;
	C(i);
	cout << "After call C" << endl;
}

void A(int i)
{
	try
	{
		B(i);
	}
	catch (int j)
	{
		cout << "catch int exception " << j << endl;
	}
	catch (double d)
	{
		cout << "catch double exception " << d << endl;
	}
	catch (MyException &e)
	{
		e.what();
	}
	catch (...)
	{
		cout << "catch other exception " << endl;
	}
}

int main(int argc, char **argv)
{
	int i;
	if (argc != 2)
	{
		cout << "Usage: " << endl;
		cout << argv[0] << " <0|1|2|3>" << endl;
		return -1;
	}

	i = strtoul(argv[1], NULL, 0);

	A(i);

	return 0;
}

```

 ![image-20230521190406631](https://pic-1304959529.cos.ap-guangzhou.myqcloud.com/DB/image-20230521190406631.png)



## 例程5

- 改进：给`class MyException`添加一个衍生类
- 捕捉函数中，应该先捕捉衍生类的异常，否则衍生类会被隐式转换成基类对象被捕获，导致捕捉异常定位不准确。
- 先捕捉小范围，再捕捉大范围

```c++

#include <iostream>
#include <string.h>
#include <unistd.h>
#include <stdlib.h>

using namespace std;

class MyException {
public:
	void what(void) { cout<<"This is MyException"<<endl; }
};

class MySubException : public MyException{
public:
	void what(void) { cout<<"This is MySubException"<<endl; }
};


void C(int i)
{
	int a = 1;
	double b= 1.2;
	float c = 1.3;

	if (i == 0)
	{
		cout<<"In C, it is OK"<<endl;
	}
	else if (i == 1)
		throw a;
	else if (i == 2)
		throw b;
	else if (i == 3)
		throw c;
	else if (i == 4)
		throw MyException();
	else if (i == 5)
		throw MySubException();
}

void B(int i)
{
	cout<<"call C ..."<<endl;
	C(i);
	cout<<"After call C"<<endl;
}

void A(int i)
{
	try {
		B(i);
	} catch (int j)
	{
		cout<<"catch int exception "<<j<<endl;
	} catch (double d)
	{
		cout<<"catch double exception "<<d<<endl;
	} catch (MySubException &e) // catch MySubException first,否则会被MyException捕获子类抛出的异常
	{
		e.what();
	} catch (MyException &e) // catch MyException second
	{
		e.what();
	} catch (...){
		cout<<"catch other exception "<<endl;
	}
}


int main(int argc, char **argv)
{
	int i;
	if (argc != 2)
	{
		cout<<"Usage: "<<endl;
		cout<<argv[0]<<" <0|1|2|3>"<<endl;
		return -1;
	}

	i = strtoul(argv[1], NULL, 0);

	A(i);
	
	return 0;
}

```

 ![image-20230521191344836](https://pic-1304959529.cos.ap-guangzhou.myqcloud.com/DB/image-20230521191344836.png)



## 例程6

- 如果不想特别去关注派生类和衍生类异常捕捉的排序，抛出异常的执行函数使用虚函数！

```c++

#include <iostream>
#include <string.h>
#include <unistd.h>
#include <stdlib.h>

using namespace std;

class MyException {
public:
	virtual void what(void) { cout<<"This is MyException"<<endl; }
};

class MySubException : public MyException{
public:
	void what(void) { cout<<"This is MySubException"<<endl; }
};


void C(int i)
{
	int a = 1;
	double b= 1.2;
	float c = 1.3;

	if (i == 0)
	{
		cout<<"In C, it is OK"<<endl;
	}
	else if (i == 1)
		throw a;
	else if (i == 2)
		throw b;
	else if (i == 3)
		throw c;
	else if (i == 4)
		throw MyException();
	else if (i == 5)
		throw MySubException();
}

void B(int i)
{
	cout<<"call C ..."<<endl;
	C(i);
	cout<<"After call C"<<endl;
}

void A(int i)
{
	try {
		B(i);
	} catch (int j)
	{
		cout<<"catch int exception "<<j<<endl;
	} catch (double d)
	{
		cout<<"catch double exception "<<d<<endl;
	} catch (MyException &e)
	{
		e.what();
	} catch (...){
		cout<<"catch other exception "<<endl;
	}
}


int main(int argc, char **argv)
{
	int i;
	if (argc != 2)
	{
		cout<<"Usage: "<<endl;
		cout<<argv[0]<<" <0|1|2|3>"<<endl;
		return -1;
	}

	i = strtoul(argv[1], NULL, 0);

	A(i);
	
	return 0;
}

```

 ![image-20230521191713576](https://pic-1304959529.cos.ap-guangzhou.myqcloud.com/DB/image-20230521191713576.png)



## 例程7

- 抛出异常的函数声明自己可能会扔出哪些异常，方便捕捉函数编写对应的捕捉处理动作

  ```c++
  void C(int i) throw(int, double)
  ```

程序：

```c++

#include <iostream>
#include <string.h>
#include <unistd.h>
#include <stdlib.h>

using namespace std;

class MyException
{
public:
	virtual void what(void)
	{
		cout << "This is MyException" << endl;
	}
};

class MySubException : public MyException
{
public:
	void what(void)
	{
		cout << "This is MySubException" << endl;
	}
};

void C(int i) throw(int, double)
{
	int a = 1;
	double b = 1.2;
	float c = 1.3;

	if (i == 0)
	{
		cout << "In C, it is OK" << endl;
	}
	else if (i == 1)
		throw a;
	else if (i == 2)
		throw b;
	else if (i == 3)
		throw c;
	else if (i == 4)
		throw MyException();
	else if (i == 5)
		throw MySubException();
}

void B(int i)
{
	cout << "call C ..." << endl;
	C(i);
	cout << "After call C" << endl;
}

void A(int i)
{
	try
	{
		B(i);
	}
	catch (int j)
	{
		cout << "catch int exception " << j << endl;
	}
	catch (double d)
	{
		cout << "catch double exception " << d << endl;
	}
	catch (MyException &e)
	{
		e.what();
	}
	catch (...)
	{
		cout << "catch other exception " << endl;
	}
}

void my_unexpected_func()
{
	cout << "my_unexpected_func" << endl;
}

void my_terminate_func()
{
	cout << "my_terminate_func" << endl;
}

int main(int argc, char **argv)
{
	int i;

	set_unexpected(my_unexpected_func);
	set_terminate(my_terminate_func);

	if (argc != 2)
	{
		cout << "Usage: " << endl;
		cout << argv[0] << " <0|1|2|3>" << endl;
		return -1;
	}

	i = strtoul(argv[1], NULL, 0);

	A(i);

	return 0;
}

```

执行结果：

 ![image-20230521192320885](https://pic-1304959529.cos.ap-guangzhou.myqcloud.com/DB/image-20230521192320885.png)

```c++
void C(int i) throw(int, double) // throw(int, double)表示只能抛出int和double类型的异常
```

- 在这种情况下，即时有对应的捕捉函数，报错也会一级一级地上抛直到有系统默认的处理函数来终止程序运行。

## 例程8

- 对于意料之外的异常,会执行2个函数：

  - `unexpected`函数(可以自己提供)，

  - `terminate`函数(可以自己提供)

    ```c++
    #include <exception>  
    void my_terminate_func ()  
        cout<<"my_terminate_func"<<endl;   
    set_terminate(my_terminate_func);
    ```

- `unexpected`函数用来处理声明之外的异常

  `terminate`函数用来处理"catch分支未捉到异常"

```c++
#include <iostream>
#include <string.h>
#include <unistd.h>
#include <stdlib.h>

using namespace std;

class MyException {
public:
	virtual void what(void) { cout<<"This is MyException"<<endl; }
};

class MySubException : public MyException{
public:
	void what(void) { cout<<"This is MySubException"<<endl; }
};


void C(int i) throw(int, double)
{
	int a = 1;
	double b= 1.2;
	float c = 1.3;

	if (i == 0)
	{
		cout<<"In C, it is OK"<<endl;
	}
	else if (i == 1)
		throw a;
	else if (i == 2)
		throw b;
	else if (i == 3)
		throw c;
	else if (i == 4)
		throw MyException();
	else if (i == 5)
		throw MySubException();
}

void B(int i)
{
	cout<<"call C ..."<<endl;
	C(i);
	cout<<"After call C"<<endl;
}

void A(int i)
{
	try {
		B(i);
	} catch (int j)
	{
		cout<<"catch int exception "<<j<<endl;
	} catch (MyException &e)
	{
		e.what();
	} 
}

void my_unexpected_func() 
{
	cout<<"my_unexpected_func"<<endl;
}

void my_terminate_func () { cout<<"my_terminate_func"<<endl; }  


int main(int argc, char **argv)
{
	int i;

	set_unexpected (my_unexpected_func);
	set_terminate(my_terminate_func);
	
	if (argc != 2)
	{
		cout<<"Usage: "<<endl;
		cout<<argv[0]<<" <0|1|2|3>"<<endl;
		return -1;
	}

	i = strtoul(argv[1], NULL, 0);

	A(i);
	
	return 0;
}


```

![image-20230521193425793](https://pic-1304959529.cos.ap-guangzhou.myqcloud.com/DB/image-20230521193425793.png)

[set_unexpected和set_terminate是C++中的异常处理函数。当程序抛出未被捕获的异常时，会调用set_terminate函数，而当程序抛出了一个未被声明的异常时，会调用set_unexpected函数。这两个函数都可以被用户重载，以便在程序出现异常时执行自定义操作。](https://cplusplus.com/reference/exception/set_unexpected/)

[set_unexpected和set_terminate都是在头文件中定义的。](https://cplusplus.com/reference/exception/set_unexpected/)
